Workbook

Sheet 보고서 표지
B2: 사업비 사용실적 보고서
B3: 세부사업명 | D3: 미래세대SWAI교육활성화
B4: 내역 사업명 | D4: 2026 정보 교원 교사연구회 CORE LAB
B5: 사업기간 | D5: 2026. 5. 28. ~ 2026. 12. 15.
B6: 총사업비(단위:원) | D6: 합 계 | F6: (정보통신진흥)기금 | H6: 자체자금 | J6: 기 타
D7: 8000000 | F7: 8000000
B8: 수행기관 | D8: (사)한국정보교육학회
B9: 총괄책임자 | D9: 성 명
D10: 연 락 처
D11: 전자우편
B12: 실무책임자 | D12: 성 명
D13: 연 락 처
D14: 전자우편
B17: 2026 정보 교원 교사 연구회 CORE LAB 사업에 대한 사업비 사용실적 보고서를 다음과 같이 제출합니다.
B20: 붙임 1. 사업비 사용실적 보고서 1부
B21: 2. 증빙자료 각 1부. 끝.
B23: 2026년 월 일
E26: 사업책임자 : (인)
E27: 수행기관 : (인)
B33: 한국과학창의재단 이사장 귀하

Sheet 사업비 사용 총괄표
B2: <붙임-사업비 사용실적 보고서>
B4: 000 사업
B5: 사업수행기관(기업명), 사업책임자(대표자), 연락처
B6: 정산담당자 연락처(이메일, 전화번호)
B11: Ⅰ. 정산총괄표
M12: (단위 : 원)
B13: 연구비예산 | E13: 연구비집행액 | H13: 이자 발생액 | K13: 반납금액(이자+사용잔액)
E14: 0 | H14: 0 | K14: =B14-E14+H14 -> 0
B17: Ⅱ. 사업비 총괄표 및 집행내역
M18: (단위 : 원)
B19: 구분 | E19: 연구비 집행계획(A) | G19: 연구비 집행액(B) | I19: 연구비 잔액(A-B) | K19: 비율
B20: 비목 | C20: 세목
B21: 인건비 | C21: 보수 | G21: ='세부비목별 집행내역서'!J13 -> 0 | I21: =E21-G21 -> 0 | K21: =E21/E46 -> #DIV/0!
C22: 상용임금 | G22: ='세부비목별 집행내역서'!J14 -> 0 | I22: =E22-G22 -> 0 | K22: =E22/E46 -> #DIV/0!
C23: 일용임금 | G23: ='세부비목별 집행내역서'!J15 -> 0 | I23: =E23-G23 -> 0 | K23: =E23/E46 -> #DIV/0!
B24: 운영비 | C24: 일반수용비 | E24: 1010000 | G24: 0 | I24: 1010000 | K24: 0
C25: 공공요금 및 제세 | E25: 5530000 | G25: 0 | I25: 5530000 | K25: 0
C26: 임차료 | E26: 0 | G26: 0 | I26: 0 | K26: 0
C27: 특금매식비 | E27: 0 | G27: 0 | I27: 0 | K27: 0
C28: 재료비 | G28: ='세부비목별 집행내역서'!J79 -> 0 | I28: =E28-G28 -> 0 | K28: =E28/E46 -> #DIV/0!
C29: 시설 및 장비 유지비 | G29: ='세부비목별 집행내역서'!J87 -> 0 | I29: =E29-G29 -> 0 | K29: =E29/E46 -> #DIV/0!
C30: 차량비 등 | G30: ='세부비목별 집행내역서'!J95 -> 0 | I30: =E30-G30 -> 0 | K30: =E30/E46 -> #DIV/0!
C31: 복리후생비 | G31: ='세부비목별 집행내역서'!J103 -> 0 | I31: =E31-G31 -> 0 | K31: =E31/E46 -> #DIV/0!
C32: 일반용역비 | G32: ='세부비목별 집행내역서'!J111 -> 0 | I32: =E32-G32 -> 0 | K32: =E32/E46 -> #DIV/0!
C33: 관리용역비 | G33: ='세부비목별 집행내역서'!J119 -> 0 | I33: =E33-G33 -> 0 | K33: =E33/E46 -> #DIV/0!
C34: 기타운영비 | E34: 160000 | G34: 0 | I34: 160000 | K34: 0
B35: 여비 | C35: 국내여비 | E35: 800000 | G35: 0 | I35: 800000 | K35: 0
C36: 국외여비 | G36: 0 | I36: =E36-G36 -> 0 | K36: =E36/E46 -> #DIV/0!
C37: 국외교육여비 | G37: 0 | I37: =E37-G37 -> 0 | K37: =E37/E46 -> #DIV/0!
B38: 업무추진비 | C38: 사업추진비 | E38: 500000 | G38: 0 | I38: 500000 | K38: 0
C39: 기관업무비 | G39: 0 | I39: =E39-G39 -> 0 | K39: =E39/E46 -> #DIV/0!
B40: 직무수행경비 | C40: 직책수행경비 | G40: 0 | I40: 0 | K40: =E40/E46 -> #DIV/0!
B41: 연구용역비 | C41: 일반연구비 | G41: ='세부비목별 집행내역서'!J167 -> 0 | I41: =E41-G41 -> 0 | K41: =E41/E46 -> #DIV/0!
B42: 유형자산 | C42: 자산취득비 | G42: ='세부비목별 집행내역서'!J177 -> 0 | I42: =E42-G42 -> 0 | K42: =E42/E46 -> #DIV/0!
B43: 민간이전 | C43: 민간경상보조 | G43: ='세부비목별 집행내역서'!J183 -> 0 | I43: =E43-G43 -> 0 | K43: =E43/E46 -> #DIV/0!
C44: 민간자본보조 | G44: ='세부비목별 집행내역서'!J184 -> 0 | I44: =E44-G44 -> 0 | K44: =E44/E46 -> #DIV/0!
C45: 민간위탁사업비 | G45: ='세부비목별 집행내역서'!J185 -> 0 | I45: =E45-G45 -> 0 | K45: =E45/E46 -> #DIV/0!
B46: 총합 | E46: 8000000 | G46: 0 | I46: 8000000 | K46: -
B47: * 사업비 예산은 사업비 변경 신청을 통해 재단에서 승인 받은 내역을 기준으로 작성해야함

Sheet 세부비목별 집행내역서
B2: [ 별지 제8호 서식 ] 세부비목별 집행내역서
B5: 세부비목별 집행내역서
B9: 1. 인건비
B10: 1) 인건비 | O10: (단위:원)
B11: 순번 | C11: 구분 (사용용도-세목/관리목) | D11: 세부내용(사용목적) | E11: 직급 | F11: 단위 | G11: 기간 (월) | H11: 단가 | I11: 참여율 | J11: 사용금액 | K11: 품의일자 | L11: 집행일자 | M11: 지급처 (상호) | N11: 결제방법 (계좌이체/카드결제) | O11: 증빙번호
B13: 1 | C13: 보수 | J13: =G13*H13*I13 -> 0
B14: 2 | C14: 상용임금 | J14: =G14*H14*I14 -> 0
B15: 3 | C15: 일용임금 | J15: =G15*H15*I15 -> 0
B16: 인건비 소계 | J16: =SUM(J13:J15) -> 0 | K16: - | L16: - | M16: - | N16: - | O16: -
B19: 2. 운영비
B20: 1) 일반수용비 | O20: (단위:원)
B21: 순번 | C21: 구분 (사용용도-세목/관리목) | D21: 세부내용(사용목적) | E21: 품명 | G21: 단위 | H21: 수량 | I21: 단가 | J21: 사용금액 | K21: 품의일자 | L21: 집행일자 | M21: 지급처 (상호) | N21: 결제방법 (계좌이체/카드결제) | O21: 증빙번호
B23: 1 | C23: 일반수용비 (사무용품 및 소모성 물품 구입비) | D23: 수업 실습 용품 구입(센서 및 회로 세트) | E23: 수업교구구입 | G23: 개 | H23: 20 | I23: 10000 | J23: =I23*H23 -> 200000 | K23: 2021.05.01 | L23: 2021.05.01 | M23: 홍길동 문구점 | N23: 카드결제 | O23: 1-01
B24: 2 | C24: 일반수용비 (사무용품 및 소모성 물품 구입비) | J24: =I24*H24 -> 0 | O24: 1-02
B25: 3 | C25: 일반수용비 (사무용품 및 소모성 물품 구입비) | J25: =I25*H25 -> 0 | O25: 1-03
C26: 일반수용비(사무용품 및 소모성 물품 구입비) 소계 | J26: =SUM(J23:J25) -> 200000 | K26: - | L26: - | M26: - | N26: - | O26: -
B27: 1 | C27: 일반수용비 (인쇄유인비 및 안내홍보물 제작비) | D27: 수업 활동지 및 자료집 인쇄비 | E27: 인쇄비 | G27: 권 | H27: 60 | I27: 5000 | J27: =I27*H27 -> 300000 | K27: 2021.05.01 | L27: 2021.05.01 | M27: ABC 인쇄소 | N27: 계좌이체 | O27: 2-01
B28: 2 | C28: 일반수용비 (인쇄유인비 및 안내홍보물 제작비) | J28: =I28*H28 -> 0 | O28: 2-02
B29: 3 | C29: 일반수용비 (인쇄유인비 및 안내홍보물 제작비) | J29: =I29*H29 -> 0 | O29: 2-03
C30: 일반수용비(인쇄유인비 및 안내홍보물 제작비) 소계 | K30: - | L30: - | M30: - | N30: - | O30: -
B31: 1 | C31: 일반수용비 (간행물 등 구입비) | D31: 간행물 | J31: =I31*H31 -> 0 | O31: 3-01
B32: 2 | C32: 일반수용비 (간행물 등 구입비) | J32: =I32*H32 -> 0 | O32: 3-02
B33: 3 | C33: 일반수용비 (간행물 등 구입비) | J33: =I33*H33 -> 0 | O33: 3-03
C34: 일반수용비(간행물 등 구입비) 소계 | J34: =SUM(J31:J33) -> 0 | K34: - | L34: - | M34: - | N34: - | O34: -
B35: 1 | C35: 일반수용비 (업무위탁대가 및 사례금) | J35: =I35*H35 -> 0 | O35: 4-01
B36: 2 | C36: 일반수용비 (업무위탁대가 및 사례금) | J36: =I36*H36 -> 0 | O36: 4-02
B37: 3 | C37: 일반수용비 (업무위탁대가 및 사례금) | J37: =I37*H37 -> 0 | O37: 4-03
C38: 일반수용비(업무위탁대가 및 사례금) 소계 | J38: =SUM(J35:J37) -> 0 | K38: - | L38: - | M38: - | N38: - | O38: -
B39: 1 | C39: 일반수용비 (각종 수수료 및 사용료) | J39: =I39*H39 -> 0 | O39: 5-01
B40: 2 | C40: 일반수용비 (각종 수수료 및 사용료) | J40: =I40*H40 -> 0 | O40: 5-02
B41: 3 | C41: 일반수용비 (각종 수수료 및 사용료) | J41: =I41*H41 -> 0 | O41: 5-03
C42: 일반수용비(각종 수수료 및 사용료) 소계 | J42: =SUM(J39:J41) -> 0 | K42: - | L42: - | M42: - | N42: - | O42: -
B43: 1 | C43: 일반수용비 (교육훈련비) | J43: =I43*H43 -> 0 | O43: 6-01
B44: 2 | C44: 일반수용비 (교육훈련비) | J44: =I44*H44 -> 0 | O44: 6-02
B45: 3 | C45: 일반수용비 (교육훈련비) | J45: =I45*H45 -> 0 | O45: 6-03
C46: 일반수용비(교육훈련비) 소계 | J46: =SUM(J43:J45) -> 0 | K46: - | L46: - | M46: - | N46: - | O46: -
B47: 일반수용비 소계 | J47: =SUM(J26,J30,J34,J38,J46, J42) -> 200000 | K47: - | L47: - | M47: - | N47: - | O47: -
B49: 2) 공공요금 및 제세 | O49: (단위:원)
B50: 순번 | C50: 구분 (사용용도-세목/관리목) | D50: 세부내용(사용목적) | E50: 품명 | G50: 단위 | H50: 수량 | I50: 단가 | J50: 사용금액 | K50: 품의일자 | L50: 집행일자 | M50: 지급처 (상호) | N50: 결제방법 (계좌이체/카드결제) | O50: 증빙번호
B52: 1 | C52: 공공요금 및 제세 | J52: =I52*H52 -> 0
...

Sheet 세부비목별 집행내역(자동)
A1: 세부비목별 집행내역서
B3: 집행 총계 | H3: 0
